Workbook
Name Slicer_Department: #N/A
Name Slicer_Performance_Category: #N/A
Name Slicer_variance_range: #N/A

Sheet  Variance Distribution Analysis

Sheet  Interactive Financial Controls

Sheet Dataset
A1: Department | B1: Month | C1: Budget | D1: Actual | E1: Variance | F1: % Variance | G1: Performance Category | H1: Total | I1: percent variance | J1: variance range | K1: average | L1: standrad deviation | Q1: total budget | R1: Total Actual
A2: Finance | B2: May | C2: 43849.81 | D2: 53116.747 | E2: 9266.9367 | F2: 21.13 | G2: =IF(F2>5,"Under Budget",IF(F2>=-5,"Within Budget",IF(F2>=-10,"Slightly Over Budget","Significantly Over Budget"))) -> Under Budget | H2: =SUM($E$2:E2) -> 9266.9367 | I2: =E2/C2*100 -> 21.133356 | J2: =IF(F2>=10,"Above +10%", IF(F2>=5,"+5% to +10%", IF(F2>=-5,"-5% to +5%", IF(F2>=-10,"-10% to -5%","Below -10%")))) -> Above +10% | K2: =AVERAGE(F:F) -> -1.9217 | L2: =_xlfn.STDEV.P(F:F) -> 25.04766 | R2: =SUM(C:C) -> 3080839.9 | S2: =SUM(D:D) -> 3020568.5
A3: Marketing | B3: May | C3: 16559.98 | D3: 19360.039 | E3: 2800.0593 | F3: 16.91 | G3: =IF(F3>5,"Under Budget",IF(F3>=-5,"Within Budget",IF(F3>=-10,"Slightly Over Budget","Significantly Over Budget"))) -> Under Budget | H3: =SUM($E$2:E3) -> 12066.996 | I3: =E3/C3*100 -> 16.908591 | J3: =IF(F3>=10,"Above +10%", IF(F3>=5,"+5% to +10%", IF(F3>=-5,"-5% to +5%", IF(F3>=-10,"-10% to -5%","Below -10%")))) -> Above +10%
A4: IT | B4: May | C4: 29375.94 | D4: 30538.745 | E4: 1162.805 | F4: 3.96 | G4: =IF(F4>5,"Under Budget",IF(F4>=-5,"Within Budget",IF(F4>=-10,"Slightly Over Budget","Significantly Over Budget"))) -> Within Budget | H4: =SUM($E$2:E4) -> 13229.801 | I4: =E4/C4*100 -> 3.9583584 | J4: =IF(F4>=10,"Above +10%", IF(F4>=5,"+5% to +10%", IF(F4>=-5,"-5% to +5%", IF(F4>=-10,"-10% to -5%","Below -10%")))) -> -5% to +5%
A5: IT | B5: May | C5: 36432.8 | D5: 37230.917 | E5: 798.11679 | F5: 2.19 | G5: =IF(F5>5,"Under Budget",IF(F5>=-5,"Within Budget",IF(F5>=-10,"Slightly Over Budget","Significantly Over Budget"))) -> Within Budget | H5: =SUM($E$2:E5) -> 14027.918 | I5: =E5/C5*100 -> 2.1906545 | J5: =IF(F5>=10,"Above +10%", IF(F5>=5,"+5% to +10%", IF(F5>=-5,"-5% to +5%", IF(F5>=-10,"-10% to -5%","Below -10%")))) -> -5% to +5%
A6: Finance | B6: May | C6: 26130.45 | D6: 19001.297 | E6: -7129.1528 | F6: -27.28 | G6: =IF(F6>5,"Under Budget",IF(F6>=-5,"Within Budget",IF(F6>=-10,"Slightly Over Budget","Significantly Over Budget"))) -> Significantly Over Budget | H6: =SUM($E$2:E6) -> 6898.765 | I6: =E6/C6*100 -> -27.282931 | J6: =IF(F6>=10,"Above +10%", IF(F6>=5,"+5% to +10%", IF(F6>=-5,"-5% to +5%", IF(F6>=-10,"-10% to -5%","Below -10%")))) -> Below -10%
A7: IT | B7: April | C7: 14968.8 | D7: 23940.467 | E7: 8971.6671 | F7: 59.94 | G7: =IF(F7>5,"Under Budget",IF(F7>=-5,"Within Budget",IF(F7>=-10,"Slightly Over Budget","Significantly Over Budget"))) -> Under Budget | H7: =SUM($E$2:E7) -> 15870.432 | I7: =E7/C7*100 -> 59.93578 | J7: =IF(F7>=10,"Above +10%", IF(F7>=5,"+5% to +10%", IF(F7>=-5,"-5% to +5%", IF(F7>=-10,"-10% to -5%","Below -10%")))) -> Above +10%
A8: IT | B8: April | C8: 19021.61 | D8: 24880.732 | E8: 5859.1219 | F8: 30.8 | G8: =IF(F8>5,"Under Budget",IF(F8>=-5,"Within Budget",IF(F8>=-10,"Slightly Over Budget","Significantly Over Budget"))) -> Under Budget | H8: =SUM($E$2:E8) -> 21729.554 | I8: =E8/C8*100 -> 30.80245 | J8: =IF(F8>=10,"Above +10%", IF(F8>=5,"+5% to +10%", IF(F8>=-5,"-5% to +5%", IF(F8>=-10,"-10% to -5%","Below -10%")))) -> Above +10%
A9: HR | B9: April | C9: 10734.71 | D9: 13987.136 | E9: 3252.4256 | F9: 30.3 | G9: =IF(F9>5,"Under Budget",IF(F9>=-5,"Within Budget",IF(F9>=-10,"Slightly Over Budget","Significantly Over Budget"))) -> Under Budget | H9: =SUM($E$2:E9) -> 24981.98 | I9: =E9/C9*100 -> 30.298216 | J9: =IF(F9>=10,"Above +10%", IF(F9>=5,"+5% to +10%", IF(F9>=-5,"-5% to +5%", IF(F9>=-10,"-10% to -5%","Below -10%")))) -> Above +10%
A10: Marketing | B10: April | C10: 33899.03 | D10: 43632.89 | E10: 9733.8596 | F10: 28.71 | G10: =IF(F10>5,"Under Budget",IF(F10>=-5,"Within Budget",IF(F10>=-10,"Slightly Over Budget","Significantly Over Budget"))) -> Under Budget | H10: =SUM($E$2:E10) -> 34715.839 | I10: =E10/C10*100 -> 28.714272 | J10: =IF(F10>=10,"Above +10%", IF(F10>=5,"+5% to +10%", IF(F10>=-5,"-5% to +5%", IF(F10>=-10,"-10% to -5%","Below -10%")))) -> Above +10%
A11: IT | B11: April | C11: 16433.02 | D11: 19533.207 | E11: 3100.1868 | F11: 18.87 | G11: =IF(F11>5,"Under Budget",IF(F11>=-5,"Within Budget",IF(F11>=-10,"Slightly Over Budget","Significantly Over Budget"))) -> Under Budget | H11: =SUM($E$2:E11) -> 37816.026 | I11: =E11/C11*100 -> 18.865594 | J11: =IF(F11>=10,"Above +10%", IF(F11>=5,"+5% to +10%", IF(F11>=-5,"-5% to +5%", IF(F11>=-10,"-10% to -5%","Below -10%")))) -> Above +10% | M11: Row Labels | N11: Sum of Actual | O11: Sum of Variance | P11: Sum of Budget
A12: HR | B12: April | C12: 32336.51 | D12: 34290.981 | E12: 1954.4713 | F12: 6.04 | G12: =IF(F12>5,"Under Budget",IF(F12>=-5,"Within Budget",IF(F12>=-10,"Slightly Over Budget","Significantly Over Budget"))) -> Under Budget | H12: =SUM($E$2:E12) -> 39770.497 | I12: =E12/C12*100 -> 6.0441628 | J12: =IF(F12>=10,"Above +10%", IF(F12>=5,"+5% to +10%", IF(F12>=-5,"-5% to +5%", IF(F12>=-10,"-10% to -5%","Below -10%")))) -> +5% to +10% | M12: January | N12: 299902.86 | O12: -9898.6584 | P12: 309801.52
A13: Finance | B13: April | C13: 49098.66 | D13: 47939.147 | E13: -1159.5125 | F13: -2.36 | G13: =IF(F13>5,"Under Budget",IF(F13>=-5,"Within Budget",IF(F13>=-10,"Slightly Over Budget","Significantly Over Budget"))) -> Within Budget | H13: =SUM($E$2:E13) -> 38610.985 | I13: =E13/C13*100 -> -2.3615971 | J13: =IF(F13>=10,"Above +10%", IF(F13>=5,"+5% to +10%", IF(F13>=-5,"-5% to +5%", IF(F13>=-10,"-10% to -5%","Below -10%")))) -> -5% to +5% | M13: February | N13: 262344.68 | O13: -9815.6781 | P13: 272160.36
A14: IT | B14: April | C14: 33791.07 | D14: 30976.085 | E14: -2814.985 | F14: -8.33 | G14: =IF(F14>5,"Under Budget",IF(F14>=-5,"Within Budget",IF(F14>=-10,"Slightly Over Budget","Significantly Over Budget"))) -> Slightly Over Budget | H14: =SUM($E$2:E14) -> 35796 | I14: =E14/C14*100 -> -8.3305591 | J14: =IF(F14>=10,"Above +10%", IF(F14>=5,"+5% to +10%", IF(F14>=-5,"-5% to +5%", IF(F14>=-10,"-10% to -5%","Below -10%")))) -> -10% to -5% | M14: March | N14: 265819.91 | O14: -29261.508 | P14: 295081.42
A15: Finance | B15: April | C15: 15836.88 | D15: 13937.296 | E15: -1899.584 | F15: -11.99 | G15: =IF(F15>5,"Under Budget",IF(F15>=-5,"Within Budget",IF(F15>=-10,"Slightly Over Budget","Significantly Over Budget"))) -> Significantly Over Budget | H15: =SUM($E$2:E15) -> 33896.416 | I15: =E15/C15*100 -> -11.994686 | J15: =IF(F15>=10,"Above +10%", IF(F15>=5,"+5% to +10%", IF(F15>=-5,"-5% to +5%", IF(F15>=-10,"-10% to -5%","Below -10%")))) -> Below -10% | M15: April | N15: 331299.47 | O15: 6792.0427 | P15: 324507.43
A16: HR | B16: April | C16: 43618.1 | D16: 37385.082 | E16: -6233.0183 | F16: -14.29 | G16: =IF(F16>5,"Under Budget",IF(F16>=-5,"Within Budget",IF(F16>=-10,"Slightly Over Budget","Significantly Over Budget"))) -> Significantly Over Budget | H16: =SUM($E$2:E16) -> 27663.397 | I16: =E16/C16*100 -> -14.289981 | J16: =IF(F16>=10,"Above +10%", IF(F16>=5,"+5% to +10%", IF(F16>=-5,"-5% to +5%", IF(F16>=-10,"-10% to -5%","Below -10%")))) -> Below -10% | M16: May | N16: 159247.75 | O16: 6898.765 | P16: 152348.98
A17: Marketing | B17: April | C17: 23037.02 | D17: 18714.111 | E17: -4322.9094 | F17: -18.77 | G17: =IF(F17>5,"Under Budget",IF(F17>=-5,"Within Budget",IF(F17>=-10,"Slightly Over Budget","Significantly Over Budget"))) -> Significantly Over Budget | H17: =SUM($E$2:E17) -> 23340.488 | I17: =E17/C17*100 -> -18.765055 | J17: =IF(F17>=10,"Above +10%", IF(F17>=5,"+5% to +10%", IF(F17>=-5,"-5% to +5%", IF(F17>=-10,"-10% to -5%","Below -10%")))) -> Below -10% | M17: June | N17: 269450.02 | O17: 10571.22 | P17: 258878.8
A18: HR | B18: April | C18: 31732.02 | D18: 22082.34 | E18: -9649.6802 | F18: -30.41 | G18: =IF(F18>5,"Under Budget",IF(F18>=-5,"Within Budget",IF(F18>=-10,"Slightly Over Budget","Significantly Over Budget"))) -> Significantly Over Budget | H18: =SUM($E$2:E18) -> 13690.808 | I18: =E18/C18*100 -> -30.409915 | J18: =IF(F18>=10,"Above +10%", IF(F18>=5,"+5% to +10%", IF(F18>=-5,"-5% to +5%", IF(F18>=-10,"-10% to -5%","Below -10%")))) -> Below -10% | M18: July | N18: 134780.75 | O18: 4113.6018 | P18: 130667.15
A19: Sales | B19: August | C19: 18822.44 | D19: 27618.836 | E19: 8796.3958 | F19: 46.73 | G19: =IF(F19>5,"Under Budget",IF(F19>=-5,"Within Budget",IF(F19>=-10,"Slightly Over Budget","Significantly Over Budget"))) -> Under Budget | H19: =SUM($E$2:E19) -> 22487.204 | I19: =E19/C19*100 -> 46.733558 | J19: =IF(F19>=10,"Above +10%", IF(F19>=5,"+5% to +10%", IF(F19>=-5,"-5% to +5%", IF(F19>=-10,"-10% to -5%","Below -10%")))) -> Above +10% | M19: August | N19: 182629 | O19: -3602.1137 | P19: 186231.11
A20: Marketing | B20: August | C20: 40282.37 | D20: 40534.674 | E20: 252.3041 | F20: 0.63 | G20: =IF(F20>5,"Under Budget",IF(F20>=-5,"Within Budget",IF(F20>=-10,"Slightly Over Budget","Significantly Over Budget"))) -> Within Budget | H20: =SUM($E$2:E20) -> 22739.508 | I20: =E20/C20*100 -> 0.62633878 | J20: =IF(F20>=10,"Above +10%", IF(F20>=5,"+5% to +10%", IF(F20>=-5,"-5% to +5%", IF(F20>=-10,"-10% to -5%","Below -10%")))) -> -5% to +5% | M20: September | N20: 131819.12 | O20: -27832.883 | P20: 159652
A21: Finance | B21: August | C21: 41336.91 | D21: 40264.283 | E21: -1072.6271 | F21: -2.59 | G21: =IF(F21>5,"Under Budget",IF(F21>=-5,"Within Budget",IF(F21>=-10,"Slightly Over Budget","Significantly Over Budget"))) -> Within Budget | H21: =SUM($E$2:E21) -> 21666.881 | I21: =E21/C21*100 -> -2.594841 | J21: =IF(F21>=10,"Above +10%", IF(F21>=5,"+5% to +10%", IF(F21>=-5,"-5% to +5%", IF(F21>=-10,"-10% to -5%","Below -10%")))) -> -5% to +5% | M21: October | N21: 239830.87 | O21: 1330.6185 | P21: 238500.25
A22: Sales | B22: August | C22: 27346.21 | D22: 23808.823 | E22: -3537.3869 | F22: -12.94 | G22: =IF(F22>5,"Under Budget",IF(F22>=-5,"Within Budget",IF(F22>=-10,"Slightly Over Budget","Significantly Over Budget"))) -> Significantly Over Budget | H22: =SUM($E$2:E22) -> 18129.494 | I22: =E22/C22*100 -> -12.935565 | J22: =IF(F22>=10,"Above +10%", IF(F22>=5,"+5% to +10%", IF(F22>=-5,"-5% to +5%", IF(F22>=-10,"-10% to -5%","Below -10%")))) -> Below -10% | M22: November | N22: 375244.26 | O22: -14307.139 | P22: 389551.4
A23: Finance | B23: August | C23: 23292.59 | D23: 20145.66 | E23: -3146.9302 | F23: -13.51 | G23: =IF(F23>5,"Under Budget",IF(F23>=-5,"Within Budget",IF(F23>=-10,"Slightly Over Budget","Significantly Over Budget"))) -> Significantly Over Budget | H23: =SUM($E$2:E23) -> 14982.564 | I23: =E23/C23*100 -> -13.510435 | J23: =IF(F23>=10,"Above +10%", IF(F23>=5,"+5% to +10%", IF(F23>=-5,"-5% to +5%", IF(F23>=-10,"-10% to -5%","Below -10%")))) -> Below -10% | M23: December | N23: 368199.85 | O23: 4740.4101 | P23: 363459.44
A24: Marketing | B24: August | C24: 35150.59 | D24: 30256.72 | E24: -4893.8695 | F24: -13.92 | G24: =IF(F24>5,"Under Budget",IF(F24>=-5,"Within Budget",IF(F24>=-10,"Slightly Over Budget","Significantly Over Budget"))) -> Significantly Over Budget | H24: =SUM($E$2:E24) -> 10088.694 | I24: =E24/C24*100 -> -13.922581 | J24: =IF(F24>=10,"Above +10%", IF(F24>=5,"+5% to +10%", IF(F24>=-5,"-5% to +5%", IF(F24>=-10,"-10% to -5%","Below -10%")))) -> Below -10% | M24: Grand Total | N24: 3020568.5 | O24: -60271.323 | P24: 3080839.9
A25: Sales | B25: December | C25: 11746.47 | D25: 21208.425 | E25: 9461.955 | F25: 80.55 | G25: =IF(F25>5,"Under Budget",IF(F25>=-5,"Within Budget",IF(F25>=-10,"Slightly Over Budget","Significantly Over Budget"))) -> Under Budget | H25: =SUM($E$2:E25) -> 19550.649 | I25: =E25/C25*100 -> 80.551476 | J25: =IF(F25>=10,"Above +10%", IF(F25>=5,"+5% to +10%", IF(F25>=-5,"-5% to +5%", IF(F25>=-10,"-10% to -5%","Below -10%")))) -> Above +10%
A26: HR | B26: December | C26: 34490.32 | D26: 41774.644 | E26: 7284.3236 | F26: 21.12 | G26: =IF(F26>5,"Under Budget",IF(F26>=-5,"Within Budget",IF(F26>=-10,"Slightly Over Budget","Significantly Over Budget"))) -> Under Budget | H26: =SUM($E$2:E26) -> 26834.973 | I26: =E26/C26*100 -> 21.119907 | J26: =IF(F26>=10,"Above +10%", IF(F26>=5,"+5% to +10%", IF(F26>=-5,"-5% to +5%", IF(F26>=-10,"-10% to -5%","Below -10%")))) -> Above +10%
A27: Marketing | B27: December | C27: 25820.61 | D27: 31190.997 | E27: 5370.3873 | F27: 20.8 | G27: =IF(F27>5,"Under Budget",IF(F27>=-5,"Within Budget",IF(F27>=-10,"Slightly Over Budget","Significantly Over Budget"))) -> Under Budget | H27: =SUM($E$2:E27) -> 32205.36 | I27: =E27/C27*100 -> 20.79884 | J27: =IF(F27>=10,"Above +10%", IF(F27>=5,"+5% to +10%", IF(F27>=-5,"-5% to +5%", IF(F27>=-10,"-10% to -5%","Below -10%")))) -> Above +10% | M27: Average of % Variance | N27: Column Labels
A28: IT | B28: December | C28: 35012.19 | D28: 39119.902 | E28: 4107.7119 | F28: 11.73 | G28: =IF(F28>5,"Under Budget",IF(F28>=-5,"Within Budget",IF(F28>=-10,"Slightly Over Budget","Significantly Over Budget"))) -> Under Budget | H28: =SUM($E$2:E28) -> 36313.072 | I28: =E28/C28*100 -> 11.732233 | J28: =IF(F28>=10,"Above +10%", IF(F28>=5,"+5% to +10%", IF(F28>=-5,"-5% to +5%", IF(F28>=-10,"-10% to -5%","Below -10%")))) -> Above +10% | M28: Row Labels | N28: January | O28: February | P28: March | Q28: April | R28: May | S28: June | T28: July | U28: August | V28: September | W28: October | X28: November | Y28: December | Z28: Grand Total
A29: IT | B29: December | C29: 39414.01 | D29: 42646.657 | E29: 3232.647 | F29: 8.2 | G29: =IF(F29>5,"Under Budget",IF(F29>=-5,"Within Budget",IF(F29>=-10,"Slightly Over Budget","Significantly Over Budget"))) -> Under Budget | H29: =SUM($E$2:E29) -> 39545.719 | I29: =E29/C29*100 -> 8.2017714 | J29: =IF(F29>=10,"Above +10%", IF(F29>=5,"+5% to +10%", IF(F29>=-5,"-5% to +5%", IF(F29>=-10,"-10% to -5%","Below -10%")))) -> +5% to +10% | M29: Finance | N29: 65.25 | O29: -21.83 | Q29: -7.175 | R29: -3.075 | S29: 15.03 | T29: 19.74 | U29: -8.05 | W29: -14.52 | X29: -16.41 | Y29: -1.38 | Z29: -0.37428571
A30: Marketing | B30: December | C30: 29171.16 | D30: 30864.574 | E30: 1693.414 | F30: 5.81 | G30: =IF(F30>5,"Under Budget",IF(F30>=-5,"Within Budget",IF(F30>=-10,"Slightly Over Budget","Significantly Over Budget"))) -> Under Budget | H30: =SUM($E$2:E30) -> 41239.133 | I30: =E30/C30*100 -> 5.8050966 | J30: =IF(F30>=10,"Above +10%", IF(F30>=5,"+5% to +10%", IF(F30>=-5,"-5% to +5%", IF(F30>=-10,"-10% to -5%","Below -10%")))) -> +5% to +10% | M30: HR | N30: 4.2066667 | O30: -3.22 | P30: -4.68 | Q30: -2.09 | S30: -7.33 | T30: 27.21 | V30: -34.595 | X30: -13.666667 | Y30: 21.12 | Z30: -4.3061111
A31: Sales | B31: December | C31: 31699.15 | D31: 32344.05 | E31: 644.89978 | F31: 2.03 | G31: =IF(F31>5,"Under Budget",IF(F31>=-5,"Within Budget",IF(F31>=-10,"Slightly Over Budget","Significantly Over Budget"))) -> Within Budget | H31: =SUM($E$2:E31) -> 41884.033 | I31: =E31/C31*100 -> 2.0344387 | J31: =IF(F31>=10,"Above +10%", IF(F31>=5,"+5% to +10%", IF(F31>=-5,"-5% to +5%", IF(F31>=-10,"-10% to -5%","Below -10%")))) -> -5% to +5% | M31: IT | N31: -10.12 | O31: -15.366667 | P31: -76.14 | Q31: 25.32 | R31: 3.075 | S31: -0.18 | T31: 16.52 | V31: -21.51 | W31: 19.17 | X31: -4.82 | Y31: 9.965 | Z31: 0.35
A32: Finance | B32: December | C32: 49374.06 | D32: 48690.316 | E32: -683.74386 | F32: -1.38 | G32: =IF(F32>5,"Under Budget",IF(F32>=-5,"Within Budget",IF(F32>=-10,"Slightly Over Budget","Significantly Over Budget"))) -> Within Budget | H32: =SUM($E$2:E32) -> 41200.289 | I32: =E32/C32*100 -> -1.3848241 | J32: =IF(F32>=10,"Above +10%", IF(F32>=5,"+5% to +10%", IF(F32>=-5,"-5% to +5%", IF(F32>=-10,"-10% to -5%","Below -10%")))) -> -5% to +5% | M32: Marketing | N32: -37.07 | O32: 17.323333 | P32: -6.5666667 | Q32: 4.97 | R32: 16.91 | S32: 42.04 | T32: -2.75 | U32: -6.645 | V32: -25.18 | W32: -12.24 | X32: 3.4175 | Y32: -11.5975 | Z32: -2.3664
A33: Sales | B33: December | C33: 26636.29 | D33: 21327.516 | E33: -5308.7741 | F33: -19.93 | G33: =IF(F33>5,"Under Budget",IF(F33>=-5,"Within Budget",IF(F33>=-10,"Slightly Over Budget","Significantly Over Budget"))) -> Significantly Over Budget | H33: =SUM($E$2:E33) -> 35891.515 | I33: =E33/C33*100 -> -19.930606 | J33: =IF(F33>=10,"Above +10%", IF(F33>=5,"+5% to +10%", IF(F33>=-5,"-5% to +5%", IF(F33>=-10,"-10% to -5%","Below -10%")))) -> Below -10% | M33: Sales | N33: -11.705 | O33: -10.8 | P33: -9.9066667 | S33: 1.855 | T33: -38.185 | U33: 16.895 | V33: -16.74 | W33: 4.36 | X33: 7.185 | Y33: 10.625 | Z33: -2.9155
A34: Sales | B34: December | C34: 39966.47 | D34: 31914.338 | E34: -8052.1321 | F34: -20.15 | G34: =IF(F34>5,"Under Budget",IF(F34>=-5,"Within Budget",IF(F34>=-10,"Slightly Over Budget","Significantly Over Budget"))) -> Significantly Over Budget | H34: =SUM($E$2:E34) -> 27839.382 | I34: =E34/C34*100 -> -20.147219 | J34: =IF(F34>=10,"Above +10%", IF(F34>=5,"+5% to +10%", IF(F34>=-5,"-5% to +5%", IF(F34>=-10,"-10% to -5%","Below -10%")))) -> Below -10% | M34: Grand Total | N34: -3.992 | O34: -3.3311111 | P34: -14.991111 | Q34: 7.3758333 | R34: 3.382 | S34: 6.61375 | T34: -2.6083333 | U34: 0.73333333 | V34: -26.524 | W34: 0.23666667 | X34: -3.2508333 | Y34: 2.9816667 | Z34: -1.9217
A35: Marketing | B35: December | C35: 29294.26 | D35: 21199.49 | E35: -8094.7698 | F35: -27.63 | G35: =IF(F35>5,"Under Budget",IF(F35>=-5,"Within Budget",IF(F35>=-10,"Slightly Over Budget","Significantly Over Budget"))) -> Significantly Over Budget | H35: =SUM($E$2:E35) -> 19744.613 | I35: =E35/C35*100 -> -27.632614 | J35: =IF(F35>=10,"Above +10%", IF(F35>=5,"+5% to +10%", IF(F35>=-5,"-5% to +5%", IF(F35>=-10,"-10% to -5%","Below -10%")))) -> Below -10%
A36: Marketing | B36: December | C36: 10834.45 | D36: 5918.9416 | E36: -4915.5084 | F36: -45.37 | G36: =IF(F36>5,"Under Budget",IF(F36>=-5,"Within Budget",IF(F36>=-10,"Slightly Over Budget","Significantly Over Budget"))) -> Significantly Over Budget | H36: =SUM($E$2:E36) -> 14829.104 | I36: =E36/C36*100 -> -45.369247 | J36: =IF(F36>=10,"Above +10%", IF(F36>=5,"+5% to +10%", IF(F36>=-5,"-5% to +5%", IF(F36>=-10,"-10% to -5%","Below -10%")))) -> Below -10%
A37: Marketing | B37: February | C37: 22883.79 | D37: 30557.983 | E37: 7674.1934 | F37: 33.54 | G37: =IF(F37>5,"Under Budget",IF(F37>=-5,"Within Budget",IF(F37>=-10,"Slightly Over Budget","Significantly Over Budget"))) -> Under Budget | H37: =SUM($E$2:E37) -> 22503.298 | I37: =E37/C37*100 -> 33.5355 | J37: =IF(F37>=10,"Above +10%", IF(F37>=5,"+5% to +10%", IF(F37>=-5,"-5% to +5%", IF(F37>=-10,"-10% to -5%","Below -10%")))) -> Above +10%
A38: Marketing | B38: February | C38: 36060.78 | D38: 45903.446 | E38: 9842.6663 | F38: 27.29 | G38: =IF(F38>5,"Under Budget",IF(F38>=-5,"Within Budget",IF(F38>=-10,"Slightly Over Budget","Significantly Over Budget"))) -> Under Budget | H38: =SUM($E$2:E38) -> 32345.964 | I38: =E38/C38*100 -> 27.294657 | J38: =IF(F38>=10,"Above +10%", IF(F38>=5,"+5% to +10%", IF(F38>=-5,"-5% to +5%", IF(F38>=-10,"-10% to -5%","Below -10%")))) -> Above +10%
A39: IT | B39: February | C39: 16466.9 | D39: 18069.145 | E39: 1602.2446 | F39: 9.73 | G39: =IF(F39>5,"Under Budget",IF(F39>=-5,"Within Budget",IF(F39>=-10,"Slightly Over Budget","Significantly Over Budget"))) -> Under Budget | H39: =SUM($E$2:E39) -> 33948.208 | I39: =E39/C39*100 -> 9.7300925 | J39: =IF(F39>=10,"Above +10%", IF(F39>=5,"+5% to +10%", IF(F39>=-5,"-5% to +5%", IF(F39>=-10,"-10% to -5%","Below -10%")))) -> +5% to +10%
A40: HR | B40: February | C40: 38971.41 | D40: 37714.718 | E40: -1256.6922 | F40: -3.22 | G40: =IF(F40>5,"Under Budget",IF(F40>=-5,"Within Budget",IF(F40>=-10,"Slightly Over Budget","Significantly Over Budget"))) -> Within Budget | H40: =SUM($E$2:E40) -> 32691.516 | I40: =E40/C40*100 -> -3.2246517 | J40: =IF(F40>=10,"Above +10%", IF(F40>=5,"+5% to +10%", IF(F40>=-5,"-5% to +5%", IF(F40>=-10,"-10% to -5%","Below -10%")))) -> -5% to +5%
...

Sheet Questions
A1: Financial Budget vs. Actual Analysis
A3: Objective: Compare budgeted vs. actual financials and generate variance reports.
A5: Dataset: Department, Month, Budget, Actual, Variance, % Variance.
A7: Tasks:
A11: Financial Budget vs. Actual Analysis Dashboard
A12: Dashboard Components & Tasks
A13: 1. Executive Summary KPIs
A15: Task: Create a high-level KPI panel showing:
A17: Total Budget vs Total Actual YTD
A19: Overall Variance (Absolute and Percentage)
A21: Number of Departments within/over budget
A23: Largest Positive Variance (Favorable)
... A131: Under Budget: Variance > +5%

Sheet Variance Trend Analysis
A1: Months | B1: Average of % Variance | I1: Cumulative trend Analysis
A2: January | B2: -3.992 | I2: Month | J2: Monthly Variance | K2: Cumulative Variance
A3: February | B3: -3.3311111 | I3: January | J3: -9898.6584 | K3: =J3 -> -9898.6584
A4: March | B4: -14.991111 | I4: February | J4: -9815.6781 | K4: =K3+J4 -> -19714.337
A5: April | B5: 7.3758333 | I5: March | J5: -29261.508 | K5: =K4+J5 -> -48975.845
A6: May | B6: 3.382 | I6: April | J6: 6792.0427 | K6: =K5+J6 -> -42183.802
A7: June | B7: 6.61375 | I7: May | J7: 6898.765 | K7: =K6+J7 -> -35285.037
A8: July | B8: -2.6083333 | I8: June | J8: 10571.22 | K8: =K7+J8 -> -24713.817
A9: August | B9: 0.73333333 | I9: July | J9: 4113.6018 | K9: =K8+J9 -> -20600.215
A10: September | B10: -26.524 | I10: August | J10: -3602.1137 | K10: =K9+J10 -> -24202.329
A11: October | B11: 0.23666667 | I11: September | J11: -27832.883 | K11: =K10+J11 -> -52035.212
A12: November | B12: -3.2508333 | I12: October | J12: 1330.6185 | K12: =K11+J12 -> -50704.594
A13: December | B13: 2.9816667 | I13: November | J13: -14307.139 | K13: =K12+J13 -> -65011.733
A14: Grand Total | B14: -1.9217 | I14: December | J14: 4740.4101 | K14: =K13+J14 -> -60271.323
A16: Row Labels | B16: Sum of Budget | C16: Sum of Actual
A17: January | B17: 309801.52 | C17: 299902.86
A18: February | B18: 272160.36 | C18: 262344.68
A19: March | B19: 295081.42 | C19: 265819.91
A20: April | B20: 324507.43 | C20: 331299.47
A21: May | B21: 152348.98 | C21: 159247.75
A22: June | B22: 258878.8 | C22: 269450.02
A23: July | B23: 130667.15 | C23: 134780.75
A24: August | B24: 186231.11 | C24: 182629
A25: September | B25: 159652 | C25: 131819.12
A26: October | B26: 238500.25 | C26: 239830.87
A27: November | B27: 389551.4 | C27: 375244.26
A28: December | B28: 363459.44 | C28: 368199.85
A29: Grand Total | B29: 3080839.9 | C29: 3020568.5
A32: Task 5: Department Performance Matrix
A33: Top/Bottom 5 departments by performance
A34: Department | B34: percent variance
A35: Sales | B35: 80.551476
A36: Finance | B36: 65.249823
A37: IT | B37: 59.93578
A38: Sales | B38: 46.733558
A39: Marketing | B39: 42.043825

Sheet dashboard
A50: Average of % Variance | B50: Column Labels
A51: Row Labels | B51: January | C51: February | D51: March | E51: April | F51: May | G51: June | H51: July | I51: August | J51: September | K51: October | L51: November | M51: December | N51: Grand Total
A52: Finance | B52: 65.25 | C52: -21.83 | E52: -7.175 | F52: -3.075 | G52: 15.03 | H52: 19.74 | I52: -8.05 | K52: -14.52 | L52: -16.41 | M52: -1.38 | N52: -0.37428571
A53: HR | B53: 4.2066667 | C53: -3.22 | D53: -4.68 | E53: -2.09 | G53: -7.33 | H53: 27.21 | J53: -34.595 | L53: -13.666667 | M53: 21.12 | N53: -4.3061111
A54: IT | B54: -10.12 | C54: -15.366667 | D54: -76.14 | E54: 25.32 | F54: 3.075 | G54: -0.18 | H54: 16.52 | J54: -21.51 | K54: 19.17 | L54: -4.82 | M54: 9.965 | N54: 0.35 | T54: Dataset!A1
A55: Marketing | B55: -37.07 | C55: 17.323333 | D55: -6.5666667 | E55: 4.97 | F55: 16.91 | G55: 42.04 | H55: -2.75 | I55: -6.645 | J55: -25.18 | K55: -12.24 | L55: 3.4175 | M55: -11.5975 | N55: -2.3664
A56: Sales | B56: -11.705 | C56: -10.8 | D56: -9.9066667 | G56: 1.855 | H56: -38.185 | I56: 16.895 | J56: -16.74 | K56: 4.36 | L56: 7.185 | M56: 10.625 | N56: -2.9155
A57: Grand Total | B57: -3.992 | C57: -3.3311111 | D57: -14.991111 | E57: 7.3758333 | F57: 3.382 | G57: 6.61375 | H57: -2.6083333 | I57: 0.73333333 | J57: -26.524 | K57: 0.23666667 | L57: -3.2508333 | M57: 2.9816667 | N57: -1.9217

Sheet Budget vs Actual Variance
A1: Row Labels | B1: Sum of Actual | C1: Sum of Budget
A2: Finance | B2: 469924.88 | C2: 476863.21
A3: HR | B3: 579626.86 | C3: 599259.41
A4: IT | B4: 715768.89 | C4: 715419.45
A5: Marketing | B5: 720364.02 | C5: 725453.54
A6: Sales | B6: 534883.89 | C6: 563844.25
A7: Grand Total | B7: 3020568.5 | C7: 3080839.9
A16: Row Labels | B16: Sum of Budget | C16: Sum of Actual | D16: Sum of Variance
A17: Finance | B17: 476863.21 | C17: 469924.88 | D17: -6938.3268
A18: HR | B18: 599259.41 | C18: 579626.86 | D18: -19632.554
A19: IT | B19: 715419.45 | C19: 715768.89 | D19: 349.43609
A20: Marketing | B20: 725453.54 | C20: 720364.02 | D20: -5089.5199
A21: Sales | B21: 563844.25 | C21: 534883.89 | D21: -28960.358
A22: Grand Total | B22: 3080839.9 | C22: 3020568.5 | D22: -60271.323

Sheet waterfall implemantation
A1: Category | B1: Value
A2: Starting Budget | B2: =SUM(Dataset!C:C) -> 3080839.9
A3: Sales Variance | B3: =SUM(Dataset!E82:E101) -> -49436.513
A4: Marketing Variance | B4: =SUM(Dataset!E57:E81) -> -10566.166
A5: IT Variance | B5: =SUM(Dataset!E34:E56) -> -36160.157
A6: HR Variance | B6: =SUM(Dataset!E16:E33) -> 1995.0988
A7: Finance Variance | B7: =SUM(Dataset!E2:E15) -> 33896.416
A8: Final Actual | B8: =SUM(Dataset!D:D) -> 3020568.5

Sheet KPI
A1: Total Budget vs Total Actual YTD | B1: =SUMIF(KPI!A:A,"*",Dataset!C:C) -> 78696.29 | D1: total budget | E1: Total Actual
D2: =SUM(Dataset!C:C) -> 3080839.9 | E2: =SUM(Dataset!D:D) -> 3020568.5
A3: Overall Variance (Absolute and Percentage)
A5: Number of Departments within/over budget | B5: =COUNTIFS(Dataset!G:G,"Within Budget") -> 19
A7: Largest Positive Variance (Favorable) | B7: =MAX(Dataset!E:E) -> 9842.6663
A9: Largest Negative Variance (Unfavorable) | B9: =MIN(Dataset!E:E) -> -9819.3919
